-------------------------------------------------------------------------------
Test set: CountingToHundredTest
-------------------------------------------------------------------------------
Tests run: 2, Failures: 1, Errors: 0, Skipped: 0, Time elapsed: 0.335 sec <<< FAILURE!
test2(CountingToHundredTest)  Time elapsed: 0.007 sec  <<< FAILURE!
java.lang.AssertionError: When input was:
-3
, the expected output was:
3-
-2
...many numbers...
98
99
100

Now the output was:

	at org.junit.Assert.fail(Assert.java:88)
	at org.junit.Assert.assertTrue(Assert.java:41)
	at CountingToHundredTest.verifyOrderOfOutput(CountingToHundredTest.java:45)
	at CountingToHundredTest.test2(CountingToHundredTest.java:22)
	at java.base/jdk.internal.reflect.NativeMethodAccessorImpl.invoke0(Native Method)
	at java.base/jdk.internal.reflect.NativeMethodAccessorImpl.invoke(NativeMethodAccessorImpl.java:62)
	at java.base/jdk.internal.reflect.DelegatingMethodAccessorImpl.invoke(DelegatingMethodAccessorImpl.java:43)
	at java.base/java.lang.reflect.Method.invoke(Method.java:567)
	at org.junit.runners.model.FrameworkMethod$1.runReflectiveCall(FrameworkMethod.java:50)
	at org.junit.internal.runners.model.ReflectiveCallable.run(ReflectiveCallable.java:12)
	at org.junit.runners.model.FrameworkMethod.invokeExplosively(FrameworkMethod.java:47)
	at org.junit.internal.runners.statements.InvokeMethod.evaluate(InvokeMethod.java:17)
	at org.junit.internal.runners.statements.FailOnTimeout$CallableStatement.call(FailOnTimeout.java:298)
	at org.junit.internal.runners.statements.FailOnTimeout$CallableStatement.call(FailOnTimeout.java:292)
	at java.base/java.util.concurrent.FutureTask.run(FutureTask.java:264)
	at java.base/java.lang.Thread.run(Thread.java:830)

